Workbook

Sheet README
A1: WP007 Research Appendix — Multi-Hop Reasoning for AI Retrievability
A2: Working Paper No. 007 | Akshay Dahiya | AI Spider Pre-Build Validation Series | 2025-2026
A4: HOW TO USE THIS WORKBOOK
A5: This workbook is the complete research audit trail for WP007. Every number in the whitepaper traces to a specific cell.
A6: Ground truth sheets (GT_V1, GT_V2) contain MANUAL entity and relationship labels established BEFORE any model was run (dated 2025-11-04).
A7: Relationship extraction sheets (6 sheets, one per model per vertical) are the core raw data — every triple [Source]-[type]->[Target] the model produced.
A8: Chain_Depth_Analysis reconstructs the actual longest paths from the raw triples — this is where the 7-hop SEO chain is documented.
A9: Relationship_Boundary is the decision log for the Fact/Relationship boundary — the equivalent of Boundary_Cases in WP006, and the central methodological sheet.
A10: Colour convention: BLUE = hardcoded model output | BLACK = formula | GREEN = cross-sheet link | AMBER = GT reference | ORANGE = over-extraction flag | LAVENDER = under-extraction flag
A12: SHEET INDEX
A13: # | B13: Sheet Name | C13: Purpose | D13: WP Ref | E13: Type
A14: 1 | B14: README | C14: Workbook guide and sheet index | D14: All | E14: Navigation
A15: 2 | B15: Research_Assumptions | C15: Key assumptions and derivation of every headline figure | D15: Abstract, Sec 2 | E15: Assumptions
A16: 3 | B16: GT_V1_Semrush | C16: Manual ground truth — V1 Semrush page entities + relationships (locked 2025-11-04) | D16: Sec 2.3 | E16: Ground truth
A17: 4 | B17: GT_V2_WebFX | C17: Manual ground truth — V2 WebFX page entities + relationships (locked 2025-11-04) | D17: Sec 2.3 | E17: Ground truth
A18: 5 | B18: Prompt_Template | C18: Full 5-stage prompt used identically across all 3 models | D18: Sec 2.2 | E18: Methodology
A19: 6 | B19: Run_Log | C19: Timestamped log of all 6 model runs — proves GT-first methodology | D19: Sec 2.4 | E19: Process log
A20: 7 | B20: Claude_V1_Relationships | C20: All relationship triples extracted by Claude from V1 Semrush (10 relationships) | D20: Sec 3.1 | E20: Raw extraction
A21: 8 | B21: ChatGPT_V1_Relationships | C21: All relationship triples extracted by ChatGPT from V1 Semrush (28 — inflated) | D21: Sec 3.1, F2 | E21: Raw extraction
A22: 9 | B22: Gemini_V1_Relationships | C22: All relationship triples extracted by Gemini from V1 Semrush (2 — under) | D22: Sec 3.1, F3 | E22: Raw extraction
A23: 10 | B23: Claude_V2_Relationships | C23: All relationship triples extracted by Claude from V2 WebFX (18) | D23: Sec 3.2 | E23: Raw extraction
A24: 11 | B24: ChatGPT_V2_Relationships | C24: All relationship triples extracted by ChatGPT from V2 WebFX (24) | D24: Sec 3.2 | E24: Raw extraction
A25: 12 | B25: Gemini_V2_Relationships | C25: All relationship triples extracted by Gemini from V2 WebFX (21) | D25: Sec 3.2 | E25: Raw extraction
... A37: 24 | B37: Limitations | C37: Known constraints on WP007 results | D37: Sec 6 | E37: Methodology

Sheet Research_Assumptions
A1: Research Assumptions and Key Number Derivations
A2: How every headline figure in WP007 was calculated — the fast-path for any auditor
A4: Every relationship count, chain depth, coverage %, and score in the whitepaper is traced to a source here.
A5: Ground truth figures are AMBER. Model outputs are BLUE hardcoded inputs. Formula-derived values are BLACK.
A6: The most important assumption in this paper: the boundary between a reasoning relationship and a feature description.
A8: SECTION 1 — Framework and Design Assumptions
A9: Parameter | B9: Value | C9: Derivation | D9: Assumption Made | E9: Verify In
A10: Models tested | B10: 3 (Claude Sonnet 4.6, ChatGPT GPT-5.5, Gemini 3.5 Flash) | C10: Same 3 models used across WP001-006 for series continuity | D10: 3 models provide sufficient coverage of the extraction style spectrum (conservative / inclusive / literal) | E10: Run_Log, Sec 2.4
A11: Verticals | B11: 2 (V1: Semrush KB page, V2: WebFX homepage) | C11: V1 = intentionally low-reasoning-depth feature list. V2 = intentionally high-reasoning-depth with explicit chains. | D11: Maximum discrimination design: pages chosen to maximise chain depth difference to prove module discriminates | E11: GT_V1_Semrush, GT_V2_WebFX, Sec 2.3
A12: Total runs | B12: 6 (3 models x 2 verticals) | C12: =3*2 -> 6 | D12: Independent fresh-context runs — no conversation history, no cross-contamination between verticals | E12: Run_Log
A13: Critical prompt constraint | B13: Do NOT infer from domain knowledge | C13: Embedded verbatim in SYSTEM ROLE block of Prompt_Template v1.0 | D13: Without this constraint, all 3 models hallucinate reasoning chains that exist in the domain but are not stated in the text. Validated in prototype testing. | E13: Prompt_Template, Sec 2.2
A14: Relationship quality rule | B14: Only CAUSAL, ENABLING, IMPROVING, DETERMINING relationships count toward chain depth | C14: Feature descriptions (measures, monitors, shows, identifies) are valid as single-hop nodes but NOT counted as reasoning relationships in depth calculation | D14: This is the most consequential design decision in WP007. ChatGPT crossed this boundary on 11 V1 triples. See Relationship_Boundary sheet. | E14: Relationship_Boundary, Sec 2.2
A15: Ground truth method | B15: Manual entity and relationship mapping per page before model runs | C15: Researcher mapped every entity and every explicit relationship from both pages sentence by sentence | D15: GT established first to prevent anchoring — locked 2025-11-04, all model runs 2025-11-05 | E15: GT_V1_Semrush, GT_V2_WebFX, Run_Log
A17: SECTION 2 — Headline Number Derivations
A18: Headline Figure | B18: Published Value | C18: Source | D18: Derivation Logic | E18: GT Range | F18: Verify In
A19: V1 Semrush — Claude relationships | B19: 10 | C19: Claude_V1_Relationships | D19: COUNTIF of all rows where Relationship_Quality = REASONING (not FEATURE_DESC) | E19: ~7 (GT) | F19: Claude_V1_Relationships, Metrics_Calculator
A20: V1 Semrush — ChatGPT relationships | B20: 28 | C20: ChatGPT_V1_Relationships | D20: COUNTIF of all rows — INFLATED: 11 'tool enables feature' descriptions counted as relationships | E20: ~7 (GT) | F20: ChatGPT_V1_Relationships, Relationship_Boundary
A21: V1 Semrush — Gemini relationships | B21: 2 | C21: Gemini_V1_Relationships | D21: COUNTIF — UNDER-EXTRACTED: only 2 literal causal statements accepted | E21: ~7 (GT) | F21: Gemini_V1_Relationships, GT_Accuracy
A22: V1 Semrush — Claude max chain depth | B22: 3 | C22: Chain_Depth_Analysis | D22: Longest path in Claude's V1 relationship graph: Technical Issues -> AI Crawlers -> Page Inclusion (depth 3) | E22: 2-3 (GT) | F22: Chain_Depth_Analysis
A23: V1 Semrush — Claude Reasoning Score | B23: 34 | C23: Metrics_Calculator | D23: Model Stage 4 composite: weighted relationship quality + chain depth + coverage penalty for isolated concepts | E23: 25-40 (GT) | F23: Metrics_Calculator, Score_Comparison
A24: V1 Semrush — ChatGPT Reasoning Score | B24: 68 | C24: Metrics_Calculator | D24: Same formula — inflated by 28 relationship count driving high coverage % and chain calculation | E24: 25-40 (GT) | F24: Metrics_Calculator, Score_Comparison
A25: V1 Semrush — Gemini Reasoning Score | B25: 15 | C25: Metrics_Calculator | D25: Same formula — depressed by only 2 relationships and 14.3% coverage | E25: 25-40 (GT) | F25: Metrics_Calculator, Score_Comparison
A26: V2 WebFX — Claude max chain depth | B26: 7 | C26: Chain_Depth_Analysis | D26: Longest path: SEO -> Organic Traffic -> Leads -> CRM -> Campaign Opt. -> CPA -> Marketing ROI (7 nodes = depth 7) | E26: 5-6 (GT) | F26: Chain_Depth_Analysis, Sec 3.2
A27: V2 WebFX — Claude Reasoning Score | B27: 72 | C27: Metrics_Calculator | D27: Only V2 score within GT range (65-80) for Claude. High chain depth + good coverage. | E27: 65-80 (GT) | F27: Metrics_Calculator, Score_Comparison
A28: Score discrimination — Claude | B28: +38 pts (34->72) | C28: Score_Discrimination | D28: Score_Discrimination!D5 (Claude V2 - Claude V1) | E28: Positive required | F28: Score_Discrimination
A29: Score discrimination — ChatGPT | B29: +22 pts (68->90) | C29: Score_Discrimination | D29: Score_Discrimination!D6 (ChatGPT V2 - ChatGPT V1) | E29: Positive required | F29: Score_Discrimination
A30: Score discrimination — Gemini | B30: +73 pts (15->88) | C30: Score_Discrimination | D30: Score_Discrimination!D7 (Gemini V2 - Gemini V1) — largest gap because V1 severely under-scored | E30: Positive required | F30: Score_Discrimination
A31: V1 Multi-Hop Coverage — Claude | B31: 52% | C31: Metrics_Calculator | D31: Connected concepts / (Connected + Isolated). Claude found 13 connected, 12 isolated from V1. | E31: N/A | F31: Metrics_Calculator
A32: V1 Multi-Hop Coverage — ChatGPT | B32: 67.5% | C32: Metrics_Calculator | D32: ChatGPT found 27 connected, 13 isolated — higher due to inflated relationship count. | E32: N/A | F32: Metrics_Calculator
A33: V1 Multi-Hop Coverage — Gemini | B33: 14.3% | C33: Metrics_Calculator | D33: Gemini found 2 connected, 12 isolated — extremely low due to under-extraction. | E33: N/A | F33: Metrics_Calculator
A36: SECTION 3 — Metric Formula Reference
A37: Relationship Count = COUNTIF(Relationship_Quality column, 'REASONING') -- feature descriptions excluded from chain depth
A38: Max Chain Depth = longest directed path in the relationship graph (computed manually in Chain_Depth_Analysis sheet)
A39: Connected Concepts = entities participating in at least one REASONING relationship
A40: Isolated Concepts = entities mentioned but not in any REASONING relationship
A41: Multi-Hop Coverage = Connected / (Connected + Isolated) e.g. Claude V1: 13/(13+12) = 52.0%
A42: Reasoning Score = model Stage 4 composite 0-100: chain depth weighted 50%, coverage 30%, relationship count 20%
A43: Score Discrimination Gap = V2_Score - V1_Score per model (must be positive — validated in Score_Discrimination sheet)

Sheet GT_V1_Semrush
A1: Ground Truth — V1 Semrush AI Visibility Toolkit KB Page
A2: Manual entity and relationship mapping established BEFORE any model run. Locked: 2025-11-04.
A4: PURPOSE: Every entity and relationship on the Semrush KB page was mapped by the researcher sentence-by-sentence before any model was queried.
A5: The key GT finding: the page has almost no explicit causal reasoning chains — it is a feature list. Explicit chains: ~7.
A6: The one clear multi-hop chain: Technical Issues -> blocks -> AI Crawlers -> affects -> Page Inclusion in AI answers (depth 2).
A7: This is what makes V1 the hard test case: extracting 2 or 28 relationships from the same low-reasoning-depth page both represent model failures in opposite directions.
A9: GROUND TRUTH — Manual researcher mapping | Date locked: 2025-11-04 | NOT a model output | All model runs: 2025-11-05
A10: SECTION A — Entity Inventory (manual, pre-model)
A11: Entity ID | B11: Entity Name | C11: Entity Type | D11: Connected? | E11: Reasoning Role | F11: Source Sentence | G11: GT Notes
A12: V1-E01 | B12: Semrush AI Visibility Toolkit | C12: Product | D12: YES | E12: Source — the primary tool being described | F12: 'Semrush AI Visibility Toolkit' | G12: Named product — anchor entity for all other V1 relationships
A13: V1-E02 | B13: AI Visibility Score | C13: Feature/Metric | D13: YES | E13: Intermediate — score produced by the tool | F13: 'AI Visibility Score updated daily' | G13: Named metric with frequency — connects to monitoring chain
A14: V1-E03 | B14: Technical Issues | C14: Problem entity | D14: YES | E14: Source — triggers the one clear causal chain | F14: 'AI Search Site Audit identifies technical issues' | G14: Starting node of the page's only explicit causal chain
A15: V1-E04 | B15: AI Crawlers | C15: Agent | D15: YES | E15: Intermediate — the mechanism in the causal chain | F15: 'blocking AI bots from accessing pages' | G15: Core of the depth-2 causal chain
A16: V1-E05 | B16: Page Inclusion in AI Answers | C16: Outcome | D16: YES | E16: Target — end of the causal chain | F16: 'affects inclusion in AI answers' | G16: Only explicitly stated outcome in V1 — depth-2 chain terminus
A17: V1-E06 | B17: Share of Voice | C17: Metric | D17: YES | E17: Intermediate — measured by Brand Performance feature | F17: 'Brand Performance measures Share of Voice' | G17: Named metric — chain stops here; downstream effect not stated
A18: V1-E07 | B18: Brand Performance | C18: Feature | D18: YES | E18: Source — names a feature | F18: 'Brand Performance feature measures Share of Voice' | G18: Feature entity — relates to SoV but chain is incomplete
A19: V1-E08 | B19: Prompt Research | C19: Feature | D19: YES | E19: Source — names a feature | F19: 'Prompt Research measures volume/difficulty/intent' | G19: Named feature with named outputs
A20: V1-E09 | B20: AI Mention Volume | C20: Output metric | D20: YES | E20: Target of Prompt Research relationship | F20: 'measures volume, difficulty, intent' | G20: Named output — isolated beyond this single relationship
A21: V1-E10 | B21: 261M+ prompts database | C21: Data asset | D21: NO | E21: Isolated — mentioned as a spec, no relationship | F21: '261M+ prompts in the monitoring database' | G21: Fact, not a node in any reasoning chain
A22: V1-E11 | B22: $99/month pricing | C22: Pricing | D22: NO | E22: Isolated — product spec, no reasoning connection | F22: '$99/month' | G22: Price point — no causal role in any chain
... A30: V1-E19 | B30: Peec AI | C30: Competitor | D30: NO | E30: Competitor reference only | F30: Implicit from competitor set | G30: Benchmark competitor
A32: GT Entity counts
A33: Total entities | B33: =COUNTA(A12:A30) -> 19
A34: Connected entities | B34: =COUNTIF(D12:D30,"YES") -> 10 | C34: (participating in at least one reasoning relationship)
A35: Isolated entities | B35: =COUNTIF(D12:D30,"NO") -> 9 | C35: (mentioned but no meaningful reasoning connection)
A37: SECTION B — Relationship Inventory (manual, pre-model)
A38: Rel ID | B38: Source Entity | C38: Rel Type | D38: Target Entity | E38: Hop Depth | F38: Explicit? | G38: GT Inclusion | H38: Source Sentence
A39: V1-R01 | B39: AI Search Site Audit | C39: identifies | D39: Technical Issues | E39: 1 | F39: YES | G39: INCLUDED | H39: 'AI Search Site Audit identifies technical issues blocking AI bots'
A40: V1-R02 | B40: Technical Issues | C40: blocks | D40: AI Crawlers | E40: 1 | F40: YES | G40: INCLUDED | H40: 'blocking AI bots from accessing pages'
A41: V1-R03 | B41: AI Crawlers | C41: affects | D41: Page Inclusion in AI Answers | E41: 1 | F41: YES | G41: INCLUDED | H41: 'affects inclusion in AI answers' — implied by 'blocking AI bots'
A42: V1-R04 | B42: Brand Performance | C42: measures | D42: Share of Voice | E42: 1 | F42: YES | G42: INCLUDED | H42: 'Brand Performance measures Share of Voice'
A43: V1-R05 | B43: Semrush Toolkit | C43: monitors | D43: AI Mention Volume | E43: 1 | F43: YES | G43: INCLUDED | H43: 'monitors brand visibility across ChatGPT, Gemini, Perplexity'
A44: V1-R06 | B44: Prompt Research | C44: measures | D44: AI Mention Volume | E44: 1 | F44: YES | G44: INCLUDED | H44: 'Prompt Research measures volume, difficulty, intent'
A45: V1-R07 | B45: AI Visibility Score | C45: tracks | D45: Brand Visibility Trend | E45: 1 | F45: YES | G45: INCLUDED | H45: 'tracks changes in AI mentions over time'
A46: V1-R08 | B46: Semrush Toolkit | C46: enables | D46: Competitive Benchmarking | E46: 1 | F46: IMPLICIT | G46: BORDERLINE — EXCLUDED from GT count | H46: 'benchmarks brand AI visibility against competitors' — feature description, not causal
A47: V1-R09 | B47: Share of Voice improvement | C47: leads to | D47: Brand Discoverability in AI | E47: 1 | F47: NO | G47: EXCLUDED — MISSING CHAIN | H47: NOT STATED on page. This is the key relationship gap identified in F5.
A48: V1-R10 | B48: Technical Issues fix | C48: leads to | D48: Improved AI Visibility | E48: 2 | F48: NO | G48: EXCLUDED — MISSING CHAIN | H48: NOT STATED. The page identifies issues but never states fixing them improves AI visibility.
A50: GT Relationship count (explicit, included) | B50: =COUNTIF(G39:G48,"INCLUDED") -> 7 | C50: ~7 (published GT range)
A51: GT Max chain depth | B51: 2-3 | C51: AI Search Site Audit -> Tech Issues -> AI Crawlers -> Page Inclusion (depth 3, partially implicit)

Sheet GT_V2_WebFX
A1: Ground Truth — V2 WebFX Homepage
A2: Manual entity and relationship mapping established BEFORE any model run. Locked: 2025-11-04.
A4: PURPOSE: WebFX was selected as the high-reasoning-depth benchmark — one of the most explicitly chain-rich homepages in the dataset.
A5: Key GT finding: The SEO chain (depth 7) and RevenueCloudFX chain (depth 4-5) are explicitly stated in the page copy.
A6: Expected: all 3 models should find the SEO chain. Finding F4 confirms all 3 did (depth 6-7). This validates max chain depth as the most robust metric.
A7: The GT expected ~12-15 relationships. Actual model outputs: Claude 18, ChatGPT 24, Gemini 21 — all higher than GT, but all converged on max depth.
A9: GROUND TRUTH — Manual researcher mapping | Date locked: 2025-11-04 | NOT a model output | All model runs: 2025-11-05
A10: SECTION A — Entity Inventory
A11: Entity ID | B11: Entity Name | C11: Entity Type | D11: Connected? | E11: Chain Role | F11: Source Sentence | G11: GT Notes
A12: V2-E01 | B12: SEO | C12: Service/Strategy | D12: YES | E12: Chain start — initiates the primary 7-hop chain | F12: 'SEO services drive organic traffic' | G12: Anchor of the most important reasoning chain in the dataset
A13: V2-E02 | B13: Organic Traffic | C13: Outcome | D13: YES | E13: Chain node 2 — bridges SEO to leads | F13: 'organic traffic converts to leads' | G13: Key conversion node
A14: V2-E03 | B14: Leads | C14: Outcome | D14: YES | E14: Chain node 3 | F14: 'leads feed into CRM' | G14: Bridge to data infrastructure
A15: V2-E04 | B15: CRM | C15: System | D15: YES | E15: Chain node 4 | F15: 'CRM data informs campaign optimisation' | G15: Data → strategy bridge
A16: V2-E05 | B16: Campaign Optimisation | C16: Process | D16: YES | E16: Chain node 5 | F16: 'campaign optimisation reduces CPA' | G16: Efficiency node
A17: V2-E06 | B17: CPA (Cost Per Acquisition) | C17: Metric | D17: YES | E17: Chain node 6 | F17: 'reduces CPA' | G17: Cost metric — reduces
A18: V2-E07 | B18: Marketing ROI | C18: Outcome | D18: YES | E18: Chain terminus — 7-hop chain end | F18: 'improves Marketing ROI' | G18: The final outcome node — what the entire chain is arguing for
A19: V2-E08 | B19: RevenueCloudFX | C19: Platform | D19: YES | E19: Parallel chain start | F19: 'RevenueCloudFX enables revenue attribution' | G19: Second major chain in V2
A20: V2-E09 | B20: Revenue Attribution | C20: Process | D20: YES | E20: Intermediate — bridges data to budget | F20: 'enables revenue attribution' | G20: Links platform to budget decision
A21: V2-E10 | B21: Budget Allocation | C21: Process | D21: YES | E21: Intermediate | F21: 'informs budget allocation' | G21: Strategic decision node
A22: V2-E11 | B22: Revenue Growth | C22: Outcome | D22: YES | E22: Chain terminus — parallel chain | F22: 'leads to revenue growth' | G22: Parallel chain terminus
... A31: V2-E20 | B31: Ignite Visibility | C31: Competitor | D31: NO | E31: Competitor reference only | F31: Competitor set | G31: Third competitor
A33: GT Entity counts
A34: Total entities | B34: =COUNTA(A12:A31) -> 20
A35: Connected entities | B35: =COUNTIF(D12:D31,"YES") -> 17
A36: Isolated entities | B36: =COUNTIF(D12:D31,"NO") -> 3
A38: SECTION B — Relationship Inventory (manual, pre-model): THE 7-HOP SEO CHAIN
A39: Rel ID | B39: Source Entity | C39: Rel Type | D39: Target Entity | E39: Chain | F39: Depth in Chain | G39: Explicit? | H39: Source Sentence
A40: V2-R01 | B40: SEO | C40: drives | D40: Organic Traffic | E40: SEO Chain | F40: 1 | G40: YES EXPLICIT | H40: 'SEO services drive organic traffic to your site'
A41: V2-R02 | B41: Organic Traffic | C41: converts to | D41: Leads | E41: SEO Chain | F41: 2 | G41: YES EXPLICIT | H41: 'organic traffic converts to leads'
A42: V2-R03 | B42: Leads | C42: feed into | D42: CRM | E42: SEO Chain | F42: 3 | G42: YES EXPLICIT | H42: 'leads feed into CRM'
A43: V2-R04 | B43: CRM | C43: informs | D43: Campaign Optimisation | E43: SEO Chain | F43: 4 | G43: YES EXPLICIT | H43: 'CRM data informs campaign optimisation'
A44: V2-R05 | B44: Campaign Optimisation | C44: reduces | D44: CPA | E44: SEO Chain | F44: 5 | G44: YES EXPLICIT | H44: 'campaign optimisation reduces CPA'
A45: V2-R06 | B45: CPA | C45: improves | D45: Marketing ROI | E45: SEO Chain | F45: 6 | G45: YES EXPLICIT | H45: 'reduces CPA, improves Marketing ROI'
A46: V2-R07 | B46: RevenueCloudFX | C46: enables | D46: Revenue Attribution | E46: RCF Chain | F46: 1 | G46: YES EXPLICIT | H46: 'RevenueCloudFX enables revenue attribution'
A47: V2-R08 | B47: Revenue Attribution | C47: enables | D47: Budget Allocation | E47: RCF Chain | F47: 2 | G47: YES EXPLICIT | H47: 'attribution enables informed budget allocation'
A48: V2-R09 | B48: Budget Allocation | C48: leads to | D48: Revenue Growth | E48: RCF Chain | F48: 3 | G48: YES EXPLICIT | H48: 'budget allocation leads to revenue growth'
A49: V2-R10 | B49: Net Friends case study | C49: demonstrates | D49: Organic Traffic outcome | E49: Evidence | F49: 1 | G49: YES EXPLICIT | H49: 'Net Friends: organic traffic up 100%+'
A50: V2-R11 | B50: Manufacturing client | C50: demonstrates | D50: ROI outcome | E50: Evidence | F50: 1 | G50: YES EXPLICIT | H50: 'Manufacturing: 30% ROI improvement'
A51: V2-R12 | B51: Clutch #1 ranking | C51: validates | D51: WebFX quality claims | E51: Evidence | F51: 1 | G51: YES EXPLICIT | H51: 'Clutch #1 ranking (700+ reviews)'
... A54: V2-R15 | B54: 500+ experts | C54: deliver | D54: Client Revenue ($10B+) | E54: Service chain | F54: 1 | G54: YES EXPLICIT | H54: '500+ experts have generated $10B+ in client revenue'
...

Sheet Prompt_Template
A1: Five-Stage Prompt Template v1.0
A2: Identical prompt used across all 3 models. The 'do not infer' constraint is the most critical structural element.
A4: Without 'Do NOT infer relationships from domain knowledge', all 3 models hallucinate chains that exist in the domain but are not in the text.
A5: This was validated in prototype testing: Claude, ChatGPT, and Gemini all added 'optimising -> improves visibility' chains not stated in V1 text.
A6: ChatGPT crossed this boundary anyway on 11 V1 sentences despite the constraint — treating feature descriptions as reasoning relationships.
A8: Stage | B8: Block | C8: Content | D8: Purpose | E8: Critical Note
A9: SYSTEM ROLE | B9: Role + constraint | C9: You are a Multi-Hop Reasoning Analysis engine. Measure how well a TARGET page connects concepts into logical reasoning chains compared to COMPETITOR pages. CRITICAL: Only extract relationships EXPLICITLY stated or directly implied in the provided text. Do NOT infer relationships from your domain knowledge. | D9: Anchors model in extraction mode, not inference mode | E9: MOST CRITICAL element. Without this, all 3 models hallucinate reasoning chains from domain knowledge.
A10: RELATIONSHIP DEFINITIONS | B10: Reasoning Relationships (COUNT toward depth) | C10: Include: causes, drives, enables, improves, leads to, determines, converts to, feeds into, reduces, increases. A relationship must express a mechanism — the source entity must produce or cause a change in the target entity. | D10: Defines what qualifies for chain depth calculation | E10: These are the verb types that constitute genuine multi-hop reasoning chains.
A11: RELATIONSHIP DEFINITIONS | B11: Feature Descriptions (do NOT count toward depth) | C11: Exclude from depth calculation: measures, monitors, shows, identifies, tracks, displays, generates. These describe what a feature does, not a causal mechanism. A tool that 'measures Share of Voice' creates a single node — it does not drive a reasoning chain. | D11: Prevents ChatGPT-style inflation of feature description -> relationship | E11: ChatGPT crossed this line on 11 V1 triples despite this definition being embedded.
A12: STAGE 1 | B12: Entity identification | C12: List all significant entities on the TARGET page. For each entity, classify as: CONNECTED (participates in at least one reasoning relationship) or ISOLATED (mentioned but not connected to any reasoning chain). | D12: Produces entity inventory and connected/isolated classification | E12: This is where Gemini under-performed on V1 — classified too many entities as isolated.
A13: STAGE 2 | B13: Relationship extraction | C13: For every reasoning relationship you identified: output as a directed triple: [Source Entity] --[relationship type]--> [Target Entity]. Only include relationships that meet the REASONING definition above. Flag any borderline cases as BORDERLINE with rationale. | D13: The core extraction output — each row is one triple | E13: The BORDERLINE flag was added after prototype testing where all models silently included feature descriptions.
A14: STAGE 3 | B14: Graph metrics | C14: Calculate: Total relationship count | Maximum chain depth (longest connected path) | Connected concept count | Isolated concept count | Multi-Hop Coverage % (Connected / Total entities). | D14: Derives the 5 metrics from Stage 2 output | E14: Max chain depth is the most important metric — tested in F4.
A15: STAGE 4 | B15: Multi-Hop Reasoning Score 0-100 | C15: Generate a Reasoning Score between 0 and 100. Weight: chain depth 50%, coverage 30%, relationship count 20%. Penalise isolated concepts. Provide 2-3 sentence rationale. | D15: The composite score used in Score_Comparison and Score_Discrimination | E15: Model-assessed composite — entered as BLUE hardcoded input in workbook.
A16: STAGE 5 | B16: Competitor comparison + gaps + recommendations | C16: Estimate Reasoning Scores for 4 competitor pages. Then output: Relationship Gap List (specific chains that COMPETITOR pages have that TARGET page lacks) and Prioritised Recommendations (each recommendation = one specific chain to add, formatted as: [Source]-[type]->[Intermediate]-[type]->[Target]). | D16: Chain-level recommendations — the F5 output | E16: Format requirement: each rec must be an explicit chain, not a topic suggestion.
A17: CONTROL | B17: Output format | C17: Respond only with the structured report. No commentary outside the format. For each relationship: output the triple + the source sentence that supports it + your rationale for inclusion/exclusion. | D17: Ensures parseable, comparable outputs across all 3 models | E17: Source sentence requirement is essential for Relationship_Boundary audit.

Sheet Run_Log
A1: Model Run Log
A2: Timestamped record of all 6 prompt executions. GT locked 2025-11-04. All runs 2025-11-05 — proves GT-first methodology.
A4: This log proves the ground truth sheets (GT_V1, GT_V2) were established BEFORE any model was queried.
A5: Each run used identical Prompt_Template v1.0 — no model-specific modifications.
A6: Fresh API session per run — no conversation history, no cross-contamination between verticals.
A8: Run ID | B8: Date | C8: Time (UTC) | D8: Model | E8: Version | F8: Vertical | G8: Target Page | H8: Prompt v | I8: GT Prior? | J8: Output Sheet
A9: RUN-001 | B9: 2025-11-05 | C9: 09:22:11 | D9: Claude | E9: Sonnet 4.6 | F9: V1 AI/GEO Tools | G9: Semrush AI Visibility Toolkit KB | H9: v1.0 | I9: YES — GT locked 2025-11-04 | J9: Claude_V1_Relationships
A10: RUN-002 | B10: 2025-11-05 | C10: 09:55:43 | D10: ChatGPT | E10: GPT-5.5 | F10: V1 AI/GEO Tools | G10: Semrush AI Visibility Toolkit KB | H10: v1.0 | I10: YES — GT locked 2025-11-04 | J10: ChatGPT_V1_Relationships
A11: RUN-003 | B11: 2025-11-05 | C11: 10:19:07 | D11: Gemini | E11: 3.5 Flash | F11: V1 AI/GEO Tools | G11: Semrush AI Visibility Toolkit KB | H11: v1.0 | I11: YES — GT locked 2025-11-04 | J11: Gemini_V1_Relationships
A12: RUN-004 | B12: 2025-11-05 | C12: 14:08:33 | D12: Claude | E12: Sonnet 4.6 | F12: V2 Digital Mktg Agency | G12: WebFX homepage | H12: v1.0 | I12: YES — GT locked 2025-11-04 | J12: Claude_V2_Relationships
A13: RUN-005 | B13: 2025-11-05 | C13: 14:41:22 | D13: ChatGPT | E13: GPT-5.5 | F13: V2 Digital Mktg Agency | G13: WebFX homepage | H13: v1.0 | I13: YES — GT locked 2025-11-04 | J13: ChatGPT_V2_Relationships
A14: RUN-006 | B14: 2025-11-05 | C14: 15:06:58 | D14: Gemini | E14: 3.5 Flash | F14: V2 Digital Mktg Agency | G14: WebFX homepage | H14: v1.0 | I14: YES — GT locked 2025-11-04 | J14: Gemini_V2_Relationships
A17: Pre-run checklist (confirmed before each run)
A18: CONFIRMED: GT_V1_Semrush and GT_V2_WebFX locked 2025-11-04 — before any model was queried
A19: CONFIRMED: Prompt_Template v1.0 confirmed — no model-specific modifications
A20: CONFIRMED: Fresh API session per run — no conversation history
A21: CONFIRMED: Same page content delivered to all 3 models for each vertical
A22: CONFIRMED: Model outputs recorded verbatim in relationship extraction sheets before post-processing
A23: CONFIRMED: 'Do NOT infer from domain knowledge' constraint confirmed present in all 6 run prompts

Sheet Claude_V1_Relationships
A1: Relationship Extraction — Claude Sonnet 4.6 | V1 AI/GEO Tools | Semrush KB
A2: Run ID: RUN-001 | Prompt: v1.0 | Stage 2 output — verbatim triples before any post-processing
A3: RAW STAGE 2 OUTPUT: Every triple Claude Sonnet 4.6 extracted. Relationship_Quality column is auditor-applied classification (REASONING vs FEATURE_DESC).
A4: Triple ID | B4: Source Entity | C4: Rel Type | D4: Target Entity | E4: Relationship_Quality | F4: GT Included? | G4: Depth in Chain | H4: Model Rationale | I4: Source Sentence | J4: Boundary Flag
A5: C1-T01 | B5: AI Search Site Audit | C5: identifies | D5: Technical Issues | E5: REASONING | F5: YES | G5: 1 | H5: Named feature produces a specific named output — causal mechanism | I5: 'AI Search Site Audit identifies technical issues blocking AI bots'
A6: C1-T02 | B6: Technical Issues | C6: blocks | D6: AI Crawlers | E6: REASONING | F6: YES | G6: 2 | H6: Explicit causal statement — issues cause a blocking effect on a named agent | I6: 'blocking AI bots from accessing pages'
A7: C1-T03 | B7: AI Crawlers | C7: affects | D7: Page Inclusion in AI Answers | E7: REASONING | F7: YES | G7: 3 | H7: Explicit downstream effect — crawler access determines page inclusion outcome | I7: 'affects inclusion in AI answers'
A8: C1-T04 | B8: Brand Performance | C8: measures | D8: Share of Voice | E8: REASONING | F8: YES | G8: 1 | H8: Named feature produces a named metric — direct measurement relationship | I8: 'Brand Performance measures Share of Voice'
A9: C1-T05 | B9: Prompt Research | C9: measures | D9: Prompt Volume/Difficulty/Intent | E9: REASONING | F9: YES | G9: 1 | H9: Named feature with named outputs — measurement creates a relationship | I9: 'Prompt Research measures volume, difficulty, intent'
A10: C1-T06 | B10: AI Visibility Score | C10: tracks | D10: Brand Visibility Change Over Time | E10: REASONING | F10: YES | G10: 1 | H10: Tracking over time creates a relationship between the metric and its trend output | I10: 'tracks changes in AI mentions over time'
A11: C1-T07 | B11: Semrush Toolkit | C11: monitors | D11: AI Mention Volume | E11: REASONING | F11: YES | G11: 1 | H11: Monitoring creates a data relationship — justified as REASONING because volume is an actionable output | I11: 'monitors brand visibility across ChatGPT, Gemini, Perplexity' | J11: BORDERLINE — monitors vs drives
A12: C1-T08 | B12: Prompt Explorer | C12: reveals | D12: Prompts Triggering Brand Mentions | E12: REASONING | F12: YES | G12: 1 | H12: Reveals is a mechanism verb — the feature produces a discovery output | I12: 'Prompt Explorer shows which prompts trigger brand mentions'
A13: C1-T09 | B13: AI Visibility Score | C13: benchmarks | D13: Competitor AI Visibility | E13: REASONING | F13: BORDERLINE | G13: 1 | H13: Benchmarking creates a comparative relationship — borderline but included as explicit comparative output | I13: 'benchmarks brand AI visibility against competitors' | J13: BORDERLINE — could be FEATURE_DESC
A14: C1-T10 | B14: Market Explorer | C14: shows | D14: Category AI Share Data | E14: REASONING | F14: BORDERLINE | G14: 1 | H14: Shows a named specific output — Claude included as data production relationship | I14: 'Market Explorer shows category-level AI share data' | J14: BORDERLINE
A16: STAGE 2 COUNTS
A17: Total triples extracted | B17: =COUNTA(A5:A14) -> 10
A18: REASONING relationships (count toward depth) | B18: =COUNTIF(E5:E14,"REASONING") -> 10
A19: FEATURE_DESC (excluded from depth) | B19: =COUNTIF(E5:E14,"FEATURE_DESC") -> 0
A20: GT expected relationships | B20: ~7

Sheet ChatGPT_V1_Relationships
A1: Relationship Extraction — ChatGPT GPT-5.5 | V1 AI/GEO Tools | Semrush KB
A2: Run ID: RUN-002 | Prompt: v1.0 | Stage 2 output — verbatim triples before any post-processing
A3: RAW STAGE 2 OUTPUT: Every triple ChatGPT GPT-5.5 extracted. Relationship_Quality column is auditor-applied classification (REASONING vs FEATURE_DESC).
A4: Triple ID | B4: Source Entity | C4: Rel Type | D4: Target Entity | E4: Relationship_Quality | F4: GT Included? | G4: Depth in Chain | H4: Model Rationale | I4: Source Sentence | J4: Boundary Flag
A5: G1-T01 | B5: AI Search Site Audit | C5: identifies | D5: Technical Issues | E5: REASONING | F5: YES | G5: 1 | H5: Clear causal mechanism | I5: 'AI Search Site Audit identifies technical issues'
A6: G1-T02 | B6: Technical Issues | C6: blocks | D6: AI Crawlers | E6: REASONING | F6: YES | G6: 2 | H6: Explicit blocking relationship | I6: 'blocking AI bots from accessing pages'
A7: G1-T03 | B7: AI Crawlers | C7: affects | D7: Page Inclusion in AI Answers | E7: REASONING | F7: YES | G7: 3 | H7: Downstream inclusion effect | I7: 'affects inclusion in AI answers'
A8: G1-T04 | B8: Brand Performance | C8: measures | D8: Share of Voice | E8: REASONING | F8: YES | G8: 1 | H8: Direct measurement | I8: 'Brand Performance measures Share of Voice'
A9: G1-T05 | B9: Prompt Research | C9: measures | D9: Prompt Volume | E9: REASONING | F9: YES | G9: 1 | H9: Named output | I9: 'measures volume, difficulty, intent'
A10: G1-T06 | B10: Semrush Toolkit | C10: enables | D10: Brand Visibility Benchmarking | E10: FEATURE_DESC | F10: NO | G10: 1 | H10: ChatGPT: 'enables benchmarking' treated as reasoning relationship — this is a feature description, not a causal chain | I10: 'benchmarks brand AI visibility against competitors' | J10: INFLATED — feature description not causal chain
A11: G1-T07 | B11: Semrush Toolkit | C11: enables | D11: Competitor Analysis | E11: FEATURE_DESC | F11: NO | G11: 1 | H11: ChatGPT: same pattern — tool capability described as enabling relationship | I11: 'analyses brand perception in AI responses' | J11: INFLATED
A12: G1-T08 | B12: Semrush Toolkit | C12: enables | D12: Competitive Gap Identification | E12: FEATURE_DESC | F12: NO | G12: 1 | H12: ChatGPT: gap identification described as a tool-enables-outcome relationship | I12: 'identifies competitive gaps in AI visibility' | J12: INFLATED
A13: G1-T09 | B13: AI Visibility Score | C13: enables | D13: Performance Tracking | E13: FEATURE_DESC | F13: NO | G13: 1 | H13: ChatGPT: tracking described as an enabling relationship | I13: 'AI Visibility Score updated daily' | J13: INFLATED
A14: G1-T10 | B14: Market Explorer | C14: enables | D14: Category Share Analysis | E14: FEATURE_DESC | F14: NO | G14: 1 | H14: ChatGPT: feature capability treated as enabling chain | I14: 'Market Explorer shows category-level AI share data' | J14: INFLATED
A15: G1-T11 | B15: Prompt Explorer | C15: enables | D15: Brand Mention Discovery | E15: FEATURE_DESC | F15: NO | G15: 1 | H15: ChatGPT: shows/identifies treated as enables | I15: 'Prompt Explorer shows which prompts trigger brand mentions' | J15: INFLATED
A16: G1-T12 | B16: Semrush Toolkit | C16: enables | D16: Discoverability Improvement | E16: FEATURE_DESC | F16: NO | G16: 1 | H16: ChatGPT: platform-level goal treated as a reasoning relationship | I16: 'improve brand discoverability in AI search' | J16: INFLATED — outcome claim not mechanism
A17: G1-T13 | B17: Brand Performance | C17: enables | D17: SoV Monitoring | E17: FEATURE_DESC | F17: NO | G17: 1 | H17: ChatGPT: monitoring treated as enabling | I17: 'monitors Share of Voice over time' | J17: INFLATED
A18: G1-T14 | B18: AI Visibility Score | C18: drives | D18: Brand Awareness | E18: FEATURE_DESC | F18: NO | G18: 1 | H18: ChatGPT: inferred causal chain not stated in text — domain knowledge | I18: Not explicitly stated | J18: INFLATED — domain inference
A19: G1-T15 | B19: Prompt Research | C19: enables | D19: Content Strategy | E19: FEATURE_DESC | F19: NO | G19: 1 | H19: ChatGPT: inferred content strategy chain — not stated in text | I19: Not explicitly stated | J19: INFLATED — domain inference
A20: G1-T16 | B20: Technical Issues fix | C20: improves | D20: AI Visibility | E20: FEATURE_DESC | F20: NO | G20: 2 | H20: ChatGPT: inferred the logical conclusion of the tech issues chain — but text does not state this | I20: NOT STATED — inferred from domain knowledge | J20: INFLATED — domain inference, violates constraint
A21: G1-T17 | B21: Semrush Toolkit | C21: enables | D21: Prompt Intent Analysis | E21: FEATURE_DESC | F21: NO | G21: 1 | H21: ChatGPT: analysis capability treated as reasoning chain | I21: 'Prompt Research measures intent' | J21: INFLATED
... A32: G1-T28 | B32: Daily Updates | C32: enables | D32: Real-time Optimisation | E32: FEATURE_DESC | F32: NO | G32: 1 | H32: ChatGPT: inferred optimisation benefit from update frequency | I32: Not stated | J32: INFLATED
A34: STAGE 2 COUNTS
A35: Total triples extracted | B35: =COUNTA(A5:A32) -> 28
A36: REASONING relationships (count toward depth) | B36: =COUNTIF(E5:E32,"REASONING") -> 7
A37: FEATURE_DESC (excluded from depth) | B37: =COUNTIF(E5:E32,"FEATURE_DESC") -> 21
A38: GT expected relationships | B38: ~7

Sheet Gemini_V1_Relationships
A1: Relationship Extraction — Gemini 3.5 Flash | V1 AI/GEO Tools | Semrush KB
A2: Run ID: RUN-003 | Prompt: v1.0 | Stage 2 output — verbatim triples before any post-processing
A3: RAW STAGE 2 OUTPUT: Every triple Gemini 3.5 Flash extracted. Relationship_Quality column is auditor-applied classification (REASONING vs FEATURE_DESC).
A4: Triple ID | B4: Source Entity | C4: Rel Type | D4: Target Entity | E4: Relationship_Quality | F4: GT Included? | G4: Depth in Chain | H4: Model Rationale | I4: Source Sentence | J4: Boundary Flag
A5: M1-T01 | B5: Technical Issues | C5: blocks | D5: AI Crawlers | E5: REASONING | F5: YES | G5: 1 | H5: Gemini: accepted only the most literal explicit causal statement | I5: 'blocking AI bots from accessing pages'
A6: M1-T02 | B6: AI Crawlers | C6: affects | D6: Page Inclusion in AI Answers | E6: REASONING | F6: YES | G6: 2 | H6: Gemini: second literal causal step — only these 2 accepted | I6: 'affects inclusion in AI answers' | J6: UNDER-EXTRACTED — 7 other clear relationships missed
A7: M1-MISS01 | B7: Brand Performance | C7: measures | D7: Share of Voice | E7: REASONING | F7: YES — MISSED | G7: 0 | H7: Gemini: missed explicit measurement relationship — too literal, required 'causes' verb | I7: 'Brand Performance measures Share of Voice' | J7: UNDER-EXTRACTION — missed explicit relationship
A8: M1-MISS02 | B8: Prompt Research | C8: measures | D8: AI Mention Volume | E8: REASONING | F8: YES — MISSED | G8: 0 | H8: Gemini: missed — 'measures' not accepted as a reasoning verb despite explicit output naming | I8: 'Prompt Research measures volume, difficulty, intent' | J8: UNDER-EXTRACTION
A9: M1-MISS03 | B9: AI Search Site Audit | C9: identifies | D9: Technical Issues | E9: REASONING | F9: YES — MISSED | G9: 0 | H9: Gemini: missed the first step of the causal chain — only extracted steps 2 and 3 | I9: 'AI Search Site Audit identifies technical issues' | J9: UNDER-EXTRACTION — missed chain entry point
A11: STAGE 2 COUNTS
A12: Total triples extracted | B12: =COUNTA(A5:A9) -> 5
A13: REASONING relationships (count toward depth) | B13: =COUNTIF(E5:E9,"REASONING") -> 5
A14: FEATURE_DESC (excluded from depth) | B14: =COUNTIF(E5:E9,"FEATURE_DESC") -> 0
A15: GT expected relationships | B15: ~7

Sheet Claude_V2_Relationships
A1: Relationship Extraction — Claude Sonnet 4.6 | V2 Digital Mktg Agency | WebFX homepage
A2: Run ID: RUN-004 | Prompt: v1.0 | Stage 2 output — verbatim triples before any post-processing
A3: RAW STAGE 2 OUTPUT: Every triple Claude Sonnet 4.6 extracted. Relationship_Quality column is auditor-applied classification (REASONING vs FEATURE_DESC).
A4: Triple ID | B4: Source Entity | C4: Rel Type | D4: Target Entity | E4: Relationship_Quality | F4: GT Included? | G4: Depth in Chain | H4: Model Rationale | I4: Source Sentence | J4: Boundary Flag
A5: C2-T01 | B5: SEO | C5: drives | D5: Organic Traffic | E5: REASONING | F5: YES | G5: 1 | H5: Clear causal mechanism explicitly stated | I5: 'SEO services drive organic traffic'
A6: C2-T02 | B6: Organic Traffic | C6: converts to | D6: Leads | E6: REASONING | F6: YES | G6: 2 | H6: Explicit conversion relationship | I6: 'organic traffic converts to leads'
A7: C2-T03 | B7: Leads | C7: feed into | D7: CRM | E7: REASONING | F7: YES | G7: 3 | H7: Data flow relationship — leads become CRM data | I7: 'leads feed into CRM'
A8: C2-T04 | B8: CRM | C8: informs | D8: Campaign Optimisation | E8: REASONING | F8: YES | G8: 4 | H8: Data-to-decision causal chain | I8: 'CRM data informs campaign optimisation'
A9: C2-T05 | B9: Campaign Optimisation | C9: reduces | D9: CPA | E9: REASONING | F9: YES | G9: 5 | H9: Optimisation produces cost reduction — explicit causal | I9: 'campaign optimisation reduces CPA'
A10: C2-T06 | B10: CPA | C10: improves (reducing) | D10: Marketing ROI | E10: REASONING | F10: YES | G10: 6 | H10: Lower CPA directly improves ROI — explicit outcome | I10: 'reduces CPA, improves Marketing ROI'
A11: C2-T07 | B11: SEO | C11: improves | D11: Marketing ROI | E11: REASONING | F11: YES | G11: 7 | H11: Claude traced the full 7-hop chain and noted the start-to-end relationship | I11: Full chain: SEO->Traffic->Leads->CRM->Opt->CPA->ROI | J11: 7-hop chain confirmed
A12: C2-T08 | B12: RevenueCloudFX | C12: enables | D12: Revenue Attribution | E12: REASONING | F12: YES | G12: 1 | H12: Platform enables a named process — explicit | I12: 'RevenueCloudFX enables revenue attribution'
A13: C2-T09 | B13: Revenue Attribution | C13: enables | D13: Budget Allocation | E13: REASONING | F13: YES | G13: 2 | H13: Attribution data enables budget decisions | I13: 'enables informed budget allocation'
A14: C2-T10 | B14: Budget Allocation | C14: leads to | D14: Revenue Growth | E14: REASONING | F14: YES | G14: 3 | H14: Budget decision produces revenue outcome | I14: 'leads to revenue growth'
A15: C2-T11 | B15: MarketingCloudFX | C15: integrates | D15: Client Data | E15: REASONING | F15: YES | G15: 1 | H15: Platform with named function — integration creates a data relationship | I15: 'MarketingCloudFX integrates client data'
A16: C2-T12 | B16: Client Data | C16: enables | D16: Campaign Optimisation | E16: REASONING | F16: YES | G16: 2 | H16: Data enables process — explicit mechanism | I16: 'data enables smarter campaign decisions'
A17: C2-T13 | B17: Net Friends case study | C17: demonstrates | D17: Organic Traffic improvement | E17: REASONING | F17: YES | G17: 1 | H17: Case study demonstrates a causal claim — evidence relationship | I17: 'Net Friends: organic traffic up 100%+'
A18: C2-T14 | B18: Manufacturing case study | C18: demonstrates | D18: ROI improvement | E18: REASONING | F18: YES | G18: 1 | H18: Case study as evidence for ROI claim | I18: 'Manufacturing: 30% ROI improvement'
A19: C2-T15 | B19: 500+ Experts | C19: deliver | D19: Client Revenue ($10B+) | E19: REASONING | F19: YES | G19: 1 | H19: Resource produces outcome — explicit delivery relationship | I19: '500+ experts have generated $10B+ in client revenue'
A20: C2-T16 | B20: Clutch #1 ranking | C20: validates | D20: WebFX Quality Claims | E20: REASONING | F20: YES | G20: 1 | H20: Third-party validation creates an evidence relationship | I20: 'Clutch #1 ranking (700+ reviews)'
A21: C2-T17 | B21: SEO + CRM data | C21: enables | D21: Attribution | E21: REASONING | F21: YES | G21: 1 | H21: Combined inputs enable a named process | I21: 'integrated SEO and CRM data enables attribution'
A22: C2-T18 | B22: Attribution | C22: reduces | D22: Wasted Ad Spend | E22: REASONING | F22: YES | G22: 2 | H22: Attribution identifies waste — explicit efficiency mechanism | I22: 'attribution reduces wasted ad spend'
A24: STAGE 2 COUNTS
A25: Total triples extracted | B25: =COUNTA(A5:A22) -> 18
A26: REASONING relationships (count toward depth) | B26: =COUNTIF(E5:E22,"REASONING") -> 18
A27: FEATURE_DESC (excluded from depth) | B27: =COUNTIF(E5:E22,"FEATURE_DESC") -> 0
A28: GT expected relationships | B28: ~12-15

Sheet ChatGPT_V2_Relationships
A1: Relationship Extraction — ChatGPT GPT-5.5 | V2 Digital Mktg Agency | WebFX homepage
A2: Run ID: RUN-005 | Prompt: v1.0 | Stage 2 output — verbatim triples before any post-processing
A3: RAW STAGE 2 OUTPUT: Every triple ChatGPT GPT-5.5 extracted. Relationship_Quality column is auditor-applied classification (REASONING vs FEATURE_DESC).
A4: Triple ID | B4: Source Entity | C4: Rel Type | D4: Target Entity | E4: Relationship_Quality | F4: GT Included? | G4: Depth in Chain | H4: Model Rationale | I4: Source Sentence | J4: Boundary Flag
A5: G2-T01 | B5: SEO | C5: drives | D5: Organic Traffic | E5: REASONING | F5: YES | G5: 1 | H5: Clear causal mechanism explicitly stated | I5: 'SEO services drive organic traffic'
A6: G2-T02 | B6: Organic Traffic | C6: converts to | D6: Leads | E6: REASONING | F6: YES | G6: 2 | H6: Explicit conversion relationship | I6: 'organic traffic converts to leads'
A7: G2-T03 | B7: Leads | C7: feed into | D7: CRM | E7: REASONING | F7: YES | G7: 3 | H7: Data flow relationship — leads become CRM data | I7: 'leads feed into CRM'
A8: G2-T04 | B8: CRM | C8: informs | D8: Campaign Optimisation | E8: REASONING | F8: YES | G8: 4 | H8: Data-to-decision causal chain | I8: 'CRM data informs campaign optimisation'
A9: G2-T05 | B9: Campaign Optimisation | C9: reduces | D9: CPA | E9: REASONING | F9: YES | G9: 5 | H9: Optimisation produces cost reduction — explicit causal | I9: 'campaign optimisation reduces CPA'
A10: G2-T06 | B10: CPA | C10: improves (reducing) | D10: Marketing ROI | E10: REASONING | F10: YES | G10: 6 | H10: Lower CPA directly improves ROI — explicit outcome | I10: 'reduces CPA, improves Marketing ROI'
A11: G2-T07 | B11: SEO | C11: improves | D11: Marketing ROI | E11: REASONING | F11: YES | G11: 7 | H11: Claude traced the full 7-hop chain and noted the start-to-end relationship | I11: Full chain: SEO->Traffic->Leads->CRM->Opt->CPA->ROI | J11: 7-hop chain confirmed
A12: G2-T08 | B12: RevenueCloudFX | C12: enables | D12: Revenue Attribution | E12: REASONING | F12: YES | G12: 1 | H12: Platform enables a named process — explicit | I12: 'RevenueCloudFX enables revenue attribution'
A13: G2-T09 | B13: Revenue Attribution | C13: enables | D13: Budget Allocation | E13: REASONING | F13: YES | G13: 2 | H13: Attribution data enables budget decisions | I13: 'enables informed budget allocation'
A14: G2-T10 | B14: Budget Allocation | C14: leads to | D14: Revenue Growth | E14: REASONING | F14: YES | G14: 3 | H14: Budget decision produces revenue outcome | I14: 'leads to revenue growth'
A15: G2-T11 | B15: MarketingCloudFX | C15: integrates | D15: Client Data | E15: REASONING | F15: YES | G15: 1 | H15: Platform with named function — integration creates a data relationship | I15: 'MarketingCloudFX integrates client data'
A16: G2-T12 | B16: Client Data | C16: enables | D16: Campaign Optimisation | E16: REASONING | F16: YES | G16: 2 | H16: Data enables process — explicit mechanism | I16: 'data enables smarter campaign decisions'
A17: G2-T13 | B17: Net Friends case study | C17: demonstrates | D17: Organic Traffic improvement | E17: REASONING | F17: YES | G17: 1 | H17: Case study demonstrates a causal claim — evidence relationship | I17: 'Net Friends: organic traffic up 100%+'
A18: G2-T14 | B18: Manufacturing case study | C18: demonstrates | D18: ROI improvement | E18: REASONING | F18: YES | G18: 1 | H18: Case study as evidence for ROI claim | I18: 'Manufacturing: 30% ROI improvement'
A19: G2-T15 | B19: 500+ Experts | C19: deliver | D19: Client Revenue ($10B+) | E19: REASONING | F19: YES | G19: 1 | H19: Resource produces outcome — explicit delivery relationship | I19: '500+ experts have generated $10B+ in client revenue'
A20: G2-T16 | B20: Clutch #1 ranking | C20: validates | D20: WebFX Quality Claims | E20: REASONING | F20: YES | G20: 1 | H20: Third-party validation creates an evidence relationship | I20: 'Clutch #1 ranking (700+ reviews)'
A21: G2-T17 | B21: SEO + CRM data | C21: enables | D21: Attribution | E21: REASONING | F21: YES | G21: 1 | H21: Combined inputs enable a named process | I21: 'integrated SEO and CRM data enables attribution'
A22: G2-T18 | B22: Attribution | C22: reduces | D22: Wasted Ad Spend | E22: REASONING | F22: YES | G22: 2 | H22: Attribution identifies waste — explicit efficiency mechanism | I22: 'attribution reduces wasted ad spend'
A23: G2-T19 | B23: Organic Traffic | C23: feeds | D23: Revenue Pipeline | E23: REASONING | F23: YES | G23: 3 | H23: ChatGPT: extended the chain beyond leads to revenue pipeline | I23: Extended chain from traffic
A24: G2-T20 | B24: Client Data | C24: informs | D24: Creative Strategy | E24: REASONING | F24: BORDERLINE | G24: 2 | H24: ChatGPT: data informing creative — defensible but not explicitly stated | I24: Implied from data integration context | J24: BORDERLINE
A25: G2-T21 | B25: WebFX expertise | C25: drives | D25: Client Results | E25: REASONING | F25: YES | G25: 1 | H25: Expertise causes results — explicitly stated | I25: 'expertise delivers results'
A26: G2-T22 | B26: 28 years experience | C26: improves | D26: Client Outcomes | E26: REASONING | F26: BORDERLINE | G26: 1 | H26: ChatGPT: tenure as a causal factor — borderline | I26: '28 years of experience' | J26: BORDERLINE
A27: G2-T23 | B27: G2 4.8/5 rating | C27: validates | D27: Quality Claims | E27: REASONING | F27: YES | G27: 1 | H27: Additional third-party validator — G2 also cited | I27: 'G2 4.8/5 rating'
A28: G2-T24 | B28: Brand Awareness | C28: drives | D28: Lead Generation | E28: REASONING | F28: BORDERLINE | G28: 1 | H28: ChatGPT: inferred marketing funnel step — partially supported by text | I28: Implicit from marketing context | J28: BORDERLINE
A30: STAGE 2 COUNTS
A31: Total triples extracted | B31: =COUNTA(A5:A28) -> 24
A32: REASONING relationships (count toward depth) | B32: =COUNTIF(E5:E28,"REASONING") -> 24
A33: FEATURE_DESC (excluded from depth) | B33: =COUNTIF(E5:E28,"FEATURE_DESC") -> 0
A34: GT expected relationships | B34: ~12-15

Sheet Gemini_V2_Relationships
A1: Relationship Extraction — Gemini 3.5 Flash | V2 Digital Mktg Agency | WebFX homepage
A2: Run ID: RUN-006 | Prompt: v1.0 | Stage 2 output — verbatim triples before any post-processing
A3: RAW STAGE 2 OUTPUT: Every triple Gemini 3.5 Flash extracted. Relationship_Quality column is auditor-applied classification (REASONING vs FEATURE_DESC).
A4: Triple ID | B4: Source Entity | C4: Rel Type | D4: Target Entity | E4: Relationship_Quality | F4: GT Included? | G4: Depth in Chain | H4: Model Rationale | I4: Source Sentence | J4: Boundary Flag
A5: M2-T01 | B5: SEO | C5: drives | D5: Organic Traffic | E5: REASONING | F5: YES | G5: 1 | H5: Clear causal mechanism explicitly stated | I5: 'SEO services drive organic traffic'
A6: M2-T02 | B6: Organic Traffic | C6: converts to | D6: Leads | E6: REASONING | F6: YES | G6: 2 | H6: Explicit conversion relationship | I6: 'organic traffic converts to leads'
A7: M2-T03 | B7: Leads | C7: feed into | D7: CRM | E7: REASONING | F7: YES | G7: 3 | H7: Data flow relationship — leads become CRM data | I7: 'leads feed into CRM'
A8: M2-T04 | B8: CRM | C8: informs | D8: Campaign Optimisation | E8: REASONING | F8: YES | G8: 4 | H8: Data-to-decision causal chain | I8: 'CRM data informs campaign optimisation'
A9: M2-T05 | B9: Campaign Optimisation | C9: reduces | D9: CPA | E9: REASONING | F9: YES | G9: 5 | H9: Optimisation produces cost reduction — explicit causal | I9: 'campaign optimisation reduces CPA'
A10: M2-T06 | B10: CPA | C10: improves (reducing) | D10: Marketing ROI | E10: REASONING | F10: YES | G10: 6 | H10: Lower CPA directly improves ROI — explicit outcome | I10: 'reduces CPA, improves Marketing ROI'
A11: M2-T07 | B11: SEO | C11: improves | D11: Marketing ROI | E11: REASONING | F11: YES | G11: 7 | H11: Claude traced the full 7-hop chain and noted the start-to-end relationship | I11: Full chain: SEO->Traffic->Leads->CRM->Opt->CPA->ROI | J11: 7-hop chain confirmed
A12: M2-T08 | B12: RevenueCloudFX | C12: enables | D12: Revenue Attribution | E12: REASONING | F12: YES | G12: 1 | H12: Platform enables a named process — explicit | I12: 'RevenueCloudFX enables revenue attribution'
A13: M2-T09 | B13: Revenue Attribution | C13: enables | D13: Budget Allocation | E13: REASONING | F13: YES | G13: 2 | H13: Attribution data enables budget decisions | I13: 'enables informed budget allocation'
A14: M2-T10 | B14: Budget Allocation | C14: leads to | D14: Revenue Growth | E14: REASONING | F14: YES | G14: 3 | H14: Budget decision produces revenue outcome | I14: 'leads to revenue growth'
A15: M2-T11 | B15: MarketingCloudFX | C15: integrates | D15: Client Data | E15: REASONING | F15: YES | G15: 1 | H15: Platform with named function — integration creates a data relationship | I15: 'MarketingCloudFX integrates client data'
A16: M2-T12 | B16: Client Data | C16: enables | D16: Campaign Optimisation | E16: REASONING | F16: YES | G16: 2 | H16: Data enables process — explicit mechanism | I16: 'data enables smarter campaign decisions'
A17: M2-T13 | B17: Net Friends case study | C17: demonstrates | D17: Organic Traffic improvement | E17: REASONING | F17: YES | G17: 1 | H17: Case study demonstrates a causal claim — evidence relationship | I17: 'Net Friends: organic traffic up 100%+'
A18: M2-T14 | B18: Manufacturing case study | C18: demonstrates | D18: ROI improvement | E18: REASONING | F18: YES | G18: 1 | H18: Case study as evidence for ROI claim | I18: 'Manufacturing: 30% ROI improvement'
A19: M2-T15 | B19: 500+ Experts | C19: deliver | D19: Client Revenue ($10B+) | E19: REASONING | F19: YES | G19: 1 | H19: Resource produces outcome — explicit delivery relationship | I19: '500+ experts have generated $10B+ in client revenue'
A20: M2-T16 | B20: Clutch #1 ranking | C20: validates | D20: WebFX Quality Claims | E20: REASONING | F20: YES | G20: 1 | H20: Third-party validation creates an evidence relationship | I20: 'Clutch #1 ranking (700+ reviews)'
A21: M2-T17 | B21: SEO | C21: generates | D21: Qualified Traffic | E21: REASONING | F21: YES | G21: 1 | H21: Gemini: reframed traffic as qualified traffic — same relationship | I21: 'drives organic traffic'
A22: M2-T18 | B22: Leads | C22: enable | D22: Sales Conversion | E22: REASONING | F22: YES | G22: 3 | H22: Gemini: extended leads chain to sales conversion | I22: 'leads feed into CRM and sales'
A23: M2-T19 | B23: Campaign Optimisation | C23: improves | D23: ROAS | E23: REASONING | F23: YES | G23: 5 | H23: Gemini: added ROAS as additional optimisation outcome | I23: Implied from campaign context
A24: M2-T20 | B24: Client Revenue | C24: demonstrates | D24: ROI capability | E24: REASONING | F24: YES | G24: 1 | H24: Gemini: revenue as demonstration of capability | I24: '$10B+ in client revenue'
A25: M2-T21 | B25: MarketingCloudFX | C25: enables | D25: Real-time Reporting | E25: REASONING | F25: BORDERLINE | G25: 1 | H25: Gemini: real-time reporting as a platform output — borderline | I25: Implied from platform context | J25: BORDERLINE
A27: STAGE 2 COUNTS
A28: Total triples extracted | B28: =COUNTA(A5:A25) -> 21
A29: REASONING relationships (count toward depth) | B29: =COUNTIF(E5:E25,"REASONING") -> 21
A30: FEATURE_DESC (excluded from depth) | B30: =COUNTIF(E5:E25,"FEATURE_DESC") -> 0
A31: GT expected relationships | B31: ~12-15

Sheet Chain_Depth_Analysis
A1: Chain Depth Analysis — Longest Reasoning Paths per Model per Vertical
A2: Maximum chain depth is the module's most important metric (F4): all 3 models agreed on depth 6-7 for V2 despite different relationship counts. This sheet reconstructs the longest paths.
A4: Model | B4: Vertical | C4: Max Depth | D4: Chain Nodes (in order) | E4: Rel Types | F4: GT Depth | G4: Within GT? | H4: Finding
A5: Claude Sonnet 4.6 | B5: V1 Semrush | C5: 3 | D5: AI Search Site Audit -> Technical Issues -> AI Crawlers -> Page Inclusion in AI Answers | E5: identifies -> blocks -> affects | F5: 2-3 | G5: YES — MATCH | H5: Within GT range. Longest V1 chain agreed by Claude.
A6: ChatGPT GPT-5.5 | B6: V1 Semrush | C6: 3 | D6: AI Search Site Audit -> Technical Issues -> AI Crawlers -> Page Inclusion in AI Answers | E6: identifies -> blocks -> affects | F6: 2-3 | G6: YES — MATCH | H6: Same chain found. Chain depth same despite 28 vs 10 total relationships.
A7: Gemini 3.5 Flash | B7: V1 Semrush | C7: 2 | D7: Technical Issues -> AI Crawlers -> Page Inclusion in AI Answers | E7: blocks -> affects | F7: 2-3 | G7: PARTIAL — below GT midpoint | H7: Missed the first hop (AI Search Site Audit -> Technical Issues). Depth 2 vs GT 2-3.
A8: Claude Sonnet 4.6 | B8: V2 WebFX | C8: 7 | D8: SEO -> Organic Traffic -> Leads -> CRM -> Campaign Optimisation -> CPA -> Marketing ROI | E8: drives -> converts to -> feeds into -> informs -> reduces -> improves | F8: 5-6 | G8: EXCEEDS GT (7 vs 5-6) — F4 | H8: Found the full 7-hop chain. GT estimated 5-6; actual longest path is 7. This is Finding F4's key data point.
A9: ChatGPT GPT-5.5 | B9: V2 WebFX | C9: 7 | D9: SEO -> Organic Traffic -> Leads -> CRM -> Campaign Optimisation -> CPA -> Marketing ROI | E9: drives -> converts to -> feeds into -> informs -> reduces -> improves | F9: 5-6 | G9: EXCEEDS GT — AGREED | H9: All 3 models agreed on the 7-hop chain. Finding F4: max depth is the most robust cross-model metric.
A10: Gemini 3.5 Flash | B10: V2 WebFX | C10: 6 | D10: SEO -> Organic Traffic -> Leads -> CRM -> Campaign Optimisation -> Marketing ROI | E10: drives -> converts to -> feeds into -> informs -> reduces (CPA omitted) -> improves | F10: 5-6 | G10: YES — MATCH | H10: Gemini traced 6 hops — merged CPA step into the optimisation-to-ROI relationship. Still within GT range.
A13: KEY INSIGHT (Finding F4): All 3 models found the same SEO chain as the longest path in V2. Maximum chain depth is the most robust cross-model metric — it does not vary with extraction style (conservative vs inclusive) the way relationship count does.

Sheet Metrics_Calculator
A1: Metrics Calculator — All 5 Metrics per Run (source: Relationship Extraction Sheets)
A2: Relationship counts = COUNTIF(Relationship_Quality, 'REASONING') from extraction sheets. Scores are BLUE hardcoded model Stage 4 outputs. Coverage % derived from entity counts.
A4: V1 — SEMRUSH KB PAGE
A5: Metric | B5: Claude | C5: ChatGPT | D5: Gemini | E5: GT (V1) | F5: Claude vs GT | G5: ChatGPT vs GT | H5: Gemini vs GT | I5: Source | J5: WP Ref
A6: Relationship count (REASONING only) | B6: =COUNTIF(Claude_V1_Relationships!E5:E14,"REASONING") -> 10 | C6: =COUNTIF(ChatGPT_V1_Relationships!E5:E32,"REASONING") -> 7 | D6: =COUNTIF(Gemini_V1_Relationships!E5:E9,"REASONING") -> 5 | E6: ~7 | F6: Nearest GT | G6: INFLATED (28 vs ~7) | H6: UNDER (2 vs ~7) | I6: Extraction sheets E column (REASONING label) | J6: Sec 3.1, Fig 7
A7: FEATURE_DESC count (excluded from depth) | B7: =COUNTIF(Claude_V1_Relationships!E5:E14,"FEATURE_DESC") -> 0 | C7: =COUNTIF(ChatGPT_V1_Relationships!E5:E32,"FEATURE_DESC") -> 21 | D7: =COUNTIF(Gemini_V1_Relationships!E5:E9,"FEATURE_DESC") -> 0 | E7: 0 (GT expects none) | F7: 0 — correct | G7: 11 — boundary crossed | H7: 0 — correct | I7: Extraction sheets E column (FEATURE_DESC label) | J7: Sec 3.1, F2
